Exception on /data [PUT]
Traceback (most recent call last):
  File "/home/nigini/Workspace/VENV/OVERCOOKED/lib/python3.8/site-packages/urllib3/connection.py", line 159, in _new_conn
    conn = connection.create_connection(
  File "/home/nigini/Workspace/VENV/OVERCOOKED/lib/python3.8/site-packages/urllib3/util/connection.py", line 61, in create_connection
    for res in socket.getaddrinfo(host, port, family, socket.SOCK_STREAM):
  File "/home/nigini/Workspace/VENV/OVERCOOKED/lib/python3.8/site-packages/eventlet/support/greendns.py", line 537, in getaddrinfo
    raise socket.gaierror(socket.EAI_NONAME, 'No address found')
socket.gaierror: [Errno -2] No address found

During handling of the above exception, another exception occurred:

Traceback (most recent call last):
  File "/home/nigini/Workspace/VENV/OVERCOOKED/lib/python3.8/site-packages/urllib3/connectionpool.py", line 670, in urlopen
    httplib_response = self._make_request(
  File "/home/nigini/Workspace/VENV/OVERCOOKED/lib/python3.8/site-packages/urllib3/connectionpool.py", line 381, in _make_request
    self._validate_conn(conn)
  File "/home/nigini/Workspace/VENV/OVERCOOKED/lib/python3.8/site-packages/urllib3/connectionpool.py", line 978, in _validate_conn
    conn.connect()
  File "/home/nigini/Workspace/VENV/OVERCOOKED/lib/python3.8/site-packages/urllib3/connection.py", line 309, in connect
    conn = self._new_conn()
  File "/home/nigini/Workspace/VENV/OVERCOOKED/lib/python3.8/site-packages/urllib3/connection.py", line 171, in _new_conn
    raise NewConnectionError(
urllib3.exceptions.NewConnectionError: <urllib3.connection.HTTPSConnection object at 0x7f39c8d36550>: Failed to establish a new connection: [Errno -2] No address found

During handling of the above exception, another exception occurred:

Traceback (most recent call last):
  File "/home/nigini/Workspace/VENV/OVERCOOKED/lib/python3.8/site-packages/requests/adapters.py", line 439, in send
    resp = conn.urlopen(
  File "/home/nigini/Workspace/VENV/OVERCOOKED/lib/python3.8/site-packages/urllib3/connectionpool.py", line 726, in urlopen
    retries = retries.increment(
  File "/home/nigini/Workspace/VENV/OVERCOOKED/lib/python3.8/site-packages/urllib3/util/retry.py", line 439, in increment
    raise MaxRetryError(_pool, url, error or ResponseError(cause))
urllib3.exceptions.MaxRetryError: HTTPSConnectionPool(host='data.labinthewild.org', port=443): Max retries exceeded with url: /v1/auth/?study_id=&study_key= (Caused by NewConnectionError('<urllib3.connection.HTTPSConnection object at 0x7f39c8d36550>: Failed to establish a new connection: [Errno -2] No address found'))

During handling of the above exception, another exception occurred:

Traceback (most recent call last):
  File "/home/nigini/Workspace/VENV/OVERCOOKED/lib/python3.8/site-packages/flask/app.py", line 2447, in wsgi_app
    response = self.full_dispatch_request()
  File "/home/nigini/Workspace/VENV/OVERCOOKED/lib/python3.8/site-packages/flask/app.py", line 1952, in full_dispatch_request
    rv = self.handle_user_exception(e)
  File "/home/nigini/Workspace/VENV/OVERCOOKED/lib/python3.8/site-packages/flask/app.py", line 1821, in handle_user_exception
    reraise(exc_type, exc_value, tb)
  File "/home/nigini/Workspace/VENV/OVERCOOKED/lib/python3.8/site-packages/flask/_compat.py", line 39, in reraise
    raise value
  File "/home/nigini/Workspace/VENV/OVERCOOKED/lib/python3.8/site-packages/flask/app.py", line 1950, in full_dispatch_request
    rv = self.dispatch_request()
  File "/home/nigini/Workspace/VENV/OVERCOOKED/lib/python3.8/site-packages/flask/app.py", line 1936, in dispatch_request
    return self.view_functions[rule.endpoint](**req.view_args)
  File "app.py", line 356, in save_data
    saved = litw_data.save_data(data['user_id'], data['study_data'])
  File "/home/nigini/Workspace/MORAL-AI/GAMES/OVERCOOKED-AI/overcooked-demo/server/litw.py", line 41, in save_data
    self._refresh_litw_token()
  File "/home/nigini/Workspace/MORAL-AI/GAMES/OVERCOOKED-AI/overcooked-demo/server/litw.py", line 30, in _refresh_litw_token
    response = requests.get(url.format(self.study_id, self.study_key))
  File "/home/nigini/Workspace/VENV/OVERCOOKED/lib/python3.8/site-packages/requests/api.py", line 76, in get
    return request('get', url, params=params, **kwargs)
  File "/home/nigini/Workspace/VENV/OVERCOOKED/lib/python3.8/site-packages/requests/api.py", line 61, in request
    return session.request(method=method, url=url, **kwargs)
  File "/home/nigini/Workspace/VENV/OVERCOOKED/lib/python3.8/site-packages/requests/sessions.py", line 530, in request
    resp = self.send(prep, **send_kwargs)
  File "/home/nigini/Workspace/VENV/OVERCOOKED/lib/python3.8/site-packages/requests/sessions.py", line 643, in send
    r = adapter.send(request, **kwargs)
  File "/home/nigini/Workspace/VENV/OVERCOOKED/lib/python3.8/site-packages/requests/adapters.py", line 516, in send
    raise ConnectionError(e, request=request)
requests.exceptions.ConnectionError: HTTPSConnectionPool(host='data.labinthewild.org', port=443): Max retries exceeded with url: /v1/auth/?study_id=&study_key= (Caused by NewConnectionError('<urllib3.connection.HTTPSConnection object at 0x7f39c8d36550>: Failed to establish a new connection: [Errno -2] No address found'))
